[2024-05-06 20:50:19,757][flwr][INFO] - Starting Flower simulation, config: num_rounds=1, no round_timeout
[2024-05-06 20:50:54,417][flwr][INFO] - Flower VCE: Ray initialized with resources: {'memory': 97351844455.0, 'node:__internal_head__': 1.0, 'GPU': 1.0, 'CPU': 40.0, 'accelerator_type:V100': 1.0, 'node:10.53.222.27': 1.0, 'object_store_memory': 46007933337.0}
[2024-05-06 20:50:54,419][flwr][INFO] - Optimize your simulation with Flower VCE: https://flower.ai/docs/framework/how-to-run-simulations.html
[2024-05-06 20:50:54,420][flwr][INFO] - Flower VCE: Resources for each Virtual Client: {'num_cpus': 2, 'num_gpus': 1.0}
[2024-05-06 20:50:54,432][flwr][INFO] - Flower VCE: Creating VirtualClientEngineActorPool with 1 actors
[2024-05-06 20:50:54,438][flwr][INFO] - [INIT]
[2024-05-06 20:50:54,439][flwr][INFO] - Requesting initial parameters from one random client
[2024-05-06 20:51:06,568][flwr][ERROR] - Traceback (most recent call last):
  File "/home/nshaheen/anaconda3/envs/grad_proj/lib/python3.9/site-packages/flwr/simulation/ray_transport/ray_client_proxy.py", line 73, in _submit_job
    out_mssg, updated_context = self.actor_pool.get_client_result(
  File "/home/nshaheen/anaconda3/envs/grad_proj/lib/python3.9/site-packages/flwr/simulation/ray_transport/ray_actor.py", line 399, in get_client_result
    return self._fetch_future_result(cid)
  File "/home/nshaheen/anaconda3/envs/grad_proj/lib/python3.9/site-packages/flwr/simulation/ray_transport/ray_actor.py", line 280, in _fetch_future_result
    res_cid, out_mssg, updated_context = ray.get(
  File "/home/nshaheen/anaconda3/envs/grad_proj/lib/python3.9/site-packages/ray/_private/auto_init_hook.py", line 24, in auto_init_wrapper
    return fn(*args, **kwargs)
  File "/home/nshaheen/anaconda3/envs/grad_proj/lib/python3.9/site-packages/ray/_private/client_mode_hook.py", line 103, in wrapper
    return func(*args, **kwargs)
  File "/home/nshaheen/anaconda3/envs/grad_proj/lib/python3.9/site-packages/ray/_private/worker.py", line 2524, in get
    raise value.as_instanceof_cause()
ray.exceptions.RayTaskError(ClientAppException): [36mray::ClientAppActor.run()[39m (pid=743123, ip=10.53.222.27, actor_id=3378543e5273e1b49b2db26901000000, repr=<flwr.simulation.ray_transport.ray_actor.ClientAppActor object at 0x7f927bf0b7c0>)
  File "/home/nshaheen/anaconda3/envs/grad_proj/lib/python3.9/site-packages/flwr/client/client_app.py", line 98, in __call__
    return self._call(message, context)
  File "/home/nshaheen/anaconda3/envs/grad_proj/lib/python3.9/site-packages/flwr/client/client_app.py", line 81, in ffn
    out_message = handle_legacy_message_from_msgtype(
  File "/home/nshaheen/anaconda3/envs/grad_proj/lib/python3.9/site-packages/flwr/client/message_handler/message_handler.py", line 96, in handle_legacy_message_from_msgtype
    client = client_fn(str(message.metadata.partition_id))
  File "/scratch/nshaheen/project/may_federated/LLaVA_flowertune/client.py", line 129, in client_fn
    return FlowerClient(
  File "/scratch/nshaheen/project/may_federated/LLaVA_flowertune/client.py", line 36, in __init__
    self.train_cfg = OmegaConf.merge(self.train_cfg, data_cfg)
  File "/home/nshaheen/anaconda3/envs/grad_proj/lib/python3.9/site-packages/omegaconf/omegaconf.py", line 273, in merge
    target.merge_with(*configs[1:])
  File "/home/nshaheen/anaconda3/envs/grad_proj/lib/python3.9/site-packages/omegaconf/basecontainer.py", line 492, in merge_with
    self._format_and_raise(key=None, value=None, cause=e)
  File "/home/nshaheen/anaconda3/envs/grad_proj/lib/python3.9/site-packages/omegaconf/base.py", line 231, in _format_and_raise
    format_and_raise(
  File "/home/nshaheen/anaconda3/envs/grad_proj/lib/python3.9/site-packages/omegaconf/_utils.py", line 819, in format_and_raise
    _raise(ex, cause)
  File "/home/nshaheen/anaconda3/envs/grad_proj/lib/python3.9/site-packages/omegaconf/_utils.py", line 797, in _raise
    raise ex.with_traceback(sys.exc_info()[2])  # set env var OC_CAUSE=1 for full trace
  File "/home/nshaheen/anaconda3/envs/grad_proj/lib/python3.9/site-packages/omegaconf/basecontainer.py", line 490, in merge_with
    self._merge_with(*others)
  File "/home/nshaheen/anaconda3/envs/grad_proj/lib/python3.9/site-packages/omegaconf/basecontainer.py", line 514, in _merge_with
    BaseContainer._map_merge(self, other)
  File "/home/nshaheen/anaconda3/envs/grad_proj/lib/python3.9/site-packages/omegaconf/basecontainer.py", line 432, in _map_merge
    dest[key] = src._get_node(key)
  File "/home/nshaheen/anaconda3/envs/grad_proj/lib/python3.9/site-packages/omegaconf/dictconfig.py", line 310, in __setitem__
    self._format_and_raise(
  File "/home/nshaheen/anaconda3/envs/grad_proj/lib/python3.9/site-packages/omegaconf/base.py", line 231, in _format_and_raise
    format_and_raise(
  File "/home/nshaheen/anaconda3/envs/grad_proj/lib/python3.9/site-packages/omegaconf/_utils.py", line 819, in format_and_raise
    _raise(ex, cause)
  File "/home/nshaheen/anaconda3/envs/grad_proj/lib/python3.9/site-packages/omegaconf/_utils.py", line 797, in _raise
    raise ex.with_traceback(sys.exc_info()[2])  # set env var OC_CAUSE=1 for full trace
  File "/home/nshaheen/anaconda3/envs/grad_proj/lib/python3.9/site-packages/omegaconf/dictconfig.py", line 308, in __setitem__
    self.__set_impl(key=key, value=value)
  File "/home/nshaheen/anaconda3/envs/grad_proj/lib/python3.9/site-packages/omegaconf/dictconfig.py", line 318, in __set_impl
    self._set_item_impl(key, value)
  File "/home/nshaheen/anaconda3/envs/grad_proj/lib/python3.9/site-packages/omegaconf/basecontainer.py", line 545, in _set_item_impl
    self._validate_set(key, value)
  File "/home/nshaheen/anaconda3/envs/grad_proj/lib/python3.9/site-packages/omegaconf/dictconfig.py", line 180, in _validate_set
    target = self._get_node(key) if key is not None else self
  File "/home/nshaheen/anaconda3/envs/grad_proj/lib/python3.9/site-packages/omegaconf/dictconfig.py", line 475, in _get_node
    self._validate_get(key)
  File "/home/nshaheen/anaconda3/envs/grad_proj/lib/python3.9/site-packages/omegaconf/dictconfig.py", line 164, in _validate_get
    self._format_and_raise(
  File "/home/nshaheen/anaconda3/envs/grad_proj/lib/python3.9/site-packages/omegaconf/base.py", line 231, in _format_and_raise
    format_and_raise(
  File "/home/nshaheen/anaconda3/envs/grad_proj/lib/python3.9/site-packages/omegaconf/_utils.py", line 899, in format_and_raise
    _raise(ex, cause)
  File "/home/nshaheen/anaconda3/envs/grad_proj/lib/python3.9/site-packages/omegaconf/_utils.py", line 797, in _raise
    raise ex.with_traceback(sys.exc_info()[2])  # set env var OC_CAUSE=1 for full trace
omegaconf.errors.ConfigKeyError: Key 'editable_path' is not in struct
    full_key: train.editable_path
    object_type=dict

The above exception was the direct cause of the following exception:

[36mray::ClientAppActor.run()[39m (pid=743123, ip=10.53.222.27, actor_id=3378543e5273e1b49b2db26901000000, repr=<flwr.simulation.ray_transport.ray_actor.ClientAppActor object at 0x7f927bf0b7c0>)
  File "/home/nshaheen/anaconda3/envs/grad_proj/lib/python3.9/site-packages/flwr/simulation/ray_transport/ray_actor.py", line 64, in run
    raise ClientAppException(str(ex)) from ex
flwr.client.client_app.ClientAppException: 
Exception ClientAppException occurred. Message: Key 'editable_path' is not in struct
    full_key: train.editable_path
    object_type=dict

[2024-05-06 20:51:06,570][flwr][ERROR] - [36mray::ClientAppActor.run()[39m (pid=743123, ip=10.53.222.27, actor_id=3378543e5273e1b49b2db26901000000, repr=<flwr.simulation.ray_transport.ray_actor.ClientAppActor object at 0x7f927bf0b7c0>)
  File "/home/nshaheen/anaconda3/envs/grad_proj/lib/python3.9/site-packages/flwr/client/client_app.py", line 98, in __call__
    return self._call(message, context)
  File "/home/nshaheen/anaconda3/envs/grad_proj/lib/python3.9/site-packages/flwr/client/client_app.py", line 81, in ffn
    out_message = handle_legacy_message_from_msgtype(
  File "/home/nshaheen/anaconda3/envs/grad_proj/lib/python3.9/site-packages/flwr/client/message_handler/message_handler.py", line 96, in handle_legacy_message_from_msgtype
    client = client_fn(str(message.metadata.partition_id))
  File "/scratch/nshaheen/project/may_federated/LLaVA_flowertune/client.py", line 129, in client_fn
    return FlowerClient(
  File "/scratch/nshaheen/project/may_federated/LLaVA_flowertune/client.py", line 36, in __init__
    self.train_cfg = OmegaConf.merge(self.train_cfg, data_cfg)
  File "/home/nshaheen/anaconda3/envs/grad_proj/lib/python3.9/site-packages/omegaconf/omegaconf.py", line 273, in merge
    target.merge_with(*configs[1:])
  File "/home/nshaheen/anaconda3/envs/grad_proj/lib/python3.9/site-packages/omegaconf/basecontainer.py", line 492, in merge_with
    self._format_and_raise(key=None, value=None, cause=e)
  File "/home/nshaheen/anaconda3/envs/grad_proj/lib/python3.9/site-packages/omegaconf/base.py", line 231, in _format_and_raise
    format_and_raise(
  File "/home/nshaheen/anaconda3/envs/grad_proj/lib/python3.9/site-packages/omegaconf/_utils.py", line 819, in format_and_raise
    _raise(ex, cause)
  File "/home/nshaheen/anaconda3/envs/grad_proj/lib/python3.9/site-packages/omegaconf/_utils.py", line 797, in _raise
    raise ex.with_traceback(sys.exc_info()[2])  # set env var OC_CAUSE=1 for full trace
  File "/home/nshaheen/anaconda3/envs/grad_proj/lib/python3.9/site-packages/omegaconf/basecontainer.py", line 490, in merge_with
    self._merge_with(*others)
  File "/home/nshaheen/anaconda3/envs/grad_proj/lib/python3.9/site-packages/omegaconf/basecontainer.py", line 514, in _merge_with
    BaseContainer._map_merge(self, other)
  File "/home/nshaheen/anaconda3/envs/grad_proj/lib/python3.9/site-packages/omegaconf/basecontainer.py", line 432, in _map_merge
    dest[key] = src._get_node(key)
  File "/home/nshaheen/anaconda3/envs/grad_proj/lib/python3.9/site-packages/omegaconf/dictconfig.py", line 310, in __setitem__
    self._format_and_raise(
  File "/home/nshaheen/anaconda3/envs/grad_proj/lib/python3.9/site-packages/omegaconf/base.py", line 231, in _format_and_raise
    format_and_raise(
  File "/home/nshaheen/anaconda3/envs/grad_proj/lib/python3.9/site-packages/omegaconf/_utils.py", line 819, in format_and_raise
    _raise(ex, cause)
  File "/home/nshaheen/anaconda3/envs/grad_proj/lib/python3.9/site-packages/omegaconf/_utils.py", line 797, in _raise
    raise ex.with_traceback(sys.exc_info()[2])  # set env var OC_CAUSE=1 for full trace
  File "/home/nshaheen/anaconda3/envs/grad_proj/lib/python3.9/site-packages/omegaconf/dictconfig.py", line 308, in __setitem__
    self.__set_impl(key=key, value=value)
  File "/home/nshaheen/anaconda3/envs/grad_proj/lib/python3.9/site-packages/omegaconf/dictconfig.py", line 318, in __set_impl
    self._set_item_impl(key, value)
  File "/home/nshaheen/anaconda3/envs/grad_proj/lib/python3.9/site-packages/omegaconf/basecontainer.py", line 545, in _set_item_impl
    self._validate_set(key, value)
  File "/home/nshaheen/anaconda3/envs/grad_proj/lib/python3.9/site-packages/omegaconf/dictconfig.py", line 180, in _validate_set
    target = self._get_node(key) if key is not None else self
  File "/home/nshaheen/anaconda3/envs/grad_proj/lib/python3.9/site-packages/omegaconf/dictconfig.py", line 475, in _get_node
    self._validate_get(key)
  File "/home/nshaheen/anaconda3/envs/grad_proj/lib/python3.9/site-packages/omegaconf/dictconfig.py", line 164, in _validate_get
    self._format_and_raise(
  File "/home/nshaheen/anaconda3/envs/grad_proj/lib/python3.9/site-packages/omegaconf/base.py", line 231, in _format_and_raise
    format_and_raise(
  File "/home/nshaheen/anaconda3/envs/grad_proj/lib/python3.9/site-packages/omegaconf/_utils.py", line 899, in format_and_raise
    _raise(ex, cause)
  File "/home/nshaheen/anaconda3/envs/grad_proj/lib/python3.9/site-packages/omegaconf/_utils.py", line 797, in _raise
    raise ex.with_traceback(sys.exc_info()[2])  # set env var OC_CAUSE=1 for full trace
omegaconf.errors.ConfigKeyError: Key 'editable_path' is not in struct
    full_key: train.editable_path
    object_type=dict

The above exception was the direct cause of the following exception:

[36mray::ClientAppActor.run()[39m (pid=743123, ip=10.53.222.27, actor_id=3378543e5273e1b49b2db26901000000, repr=<flwr.simulation.ray_transport.ray_actor.ClientAppActor object at 0x7f927bf0b7c0>)
  File "/home/nshaheen/anaconda3/envs/grad_proj/lib/python3.9/site-packages/flwr/simulation/ray_transport/ray_actor.py", line 64, in run
    raise ClientAppException(str(ex)) from ex
flwr.client.client_app.ClientAppException: 
Exception ClientAppException occurred. Message: Key 'editable_path' is not in struct
    full_key: train.editable_path
    object_type=dict
[2024-05-06 20:51:06,572][flwr][ERROR] - [36mray::ClientAppActor.run()[39m (pid=743123, ip=10.53.222.27, actor_id=3378543e5273e1b49b2db26901000000, repr=<flwr.simulation.ray_transport.ray_actor.ClientAppActor object at 0x7f927bf0b7c0>)
  File "/home/nshaheen/anaconda3/envs/grad_proj/lib/python3.9/site-packages/flwr/client/client_app.py", line 98, in __call__
    return self._call(message, context)
  File "/home/nshaheen/anaconda3/envs/grad_proj/lib/python3.9/site-packages/flwr/client/client_app.py", line 81, in ffn
    out_message = handle_legacy_message_from_msgtype(
  File "/home/nshaheen/anaconda3/envs/grad_proj/lib/python3.9/site-packages/flwr/client/message_handler/message_handler.py", line 96, in handle_legacy_message_from_msgtype
    client = client_fn(str(message.metadata.partition_id))
  File "/scratch/nshaheen/project/may_federated/LLaVA_flowertune/client.py", line 129, in client_fn
    return FlowerClient(
  File "/scratch/nshaheen/project/may_federated/LLaVA_flowertune/client.py", line 36, in __init__
    self.train_cfg = OmegaConf.merge(self.train_cfg, data_cfg)
  File "/home/nshaheen/anaconda3/envs/grad_proj/lib/python3.9/site-packages/omegaconf/omegaconf.py", line 273, in merge
    target.merge_with(*configs[1:])
  File "/home/nshaheen/anaconda3/envs/grad_proj/lib/python3.9/site-packages/omegaconf/basecontainer.py", line 492, in merge_with
    self._format_and_raise(key=None, value=None, cause=e)
  File "/home/nshaheen/anaconda3/envs/grad_proj/lib/python3.9/site-packages/omegaconf/base.py", line 231, in _format_and_raise
    format_and_raise(
  File "/home/nshaheen/anaconda3/envs/grad_proj/lib/python3.9/site-packages/omegaconf/_utils.py", line 819, in format_and_raise
    _raise(ex, cause)
  File "/home/nshaheen/anaconda3/envs/grad_proj/lib/python3.9/site-packages/omegaconf/_utils.py", line 797, in _raise
    raise ex.with_traceback(sys.exc_info()[2])  # set env var OC_CAUSE=1 for full trace
  File "/home/nshaheen/anaconda3/envs/grad_proj/lib/python3.9/site-packages/omegaconf/basecontainer.py", line 490, in merge_with
    self._merge_with(*others)
  File "/home/nshaheen/anaconda3/envs/grad_proj/lib/python3.9/site-packages/omegaconf/basecontainer.py", line 514, in _merge_with
    BaseContainer._map_merge(self, other)
  File "/home/nshaheen/anaconda3/envs/grad_proj/lib/python3.9/site-packages/omegaconf/basecontainer.py", line 432, in _map_merge
    dest[key] = src._get_node(key)
  File "/home/nshaheen/anaconda3/envs/grad_proj/lib/python3.9/site-packages/omegaconf/dictconfig.py", line 310, in __setitem__
    self._format_and_raise(
  File "/home/nshaheen/anaconda3/envs/grad_proj/lib/python3.9/site-packages/omegaconf/base.py", line 231, in _format_and_raise
    format_and_raise(
  File "/home/nshaheen/anaconda3/envs/grad_proj/lib/python3.9/site-packages/omegaconf/_utils.py", line 819, in format_and_raise
    _raise(ex, cause)
  File "/home/nshaheen/anaconda3/envs/grad_proj/lib/python3.9/site-packages/omegaconf/_utils.py", line 797, in _raise
    raise ex.with_traceback(sys.exc_info()[2])  # set env var OC_CAUSE=1 for full trace
  File "/home/nshaheen/anaconda3/envs/grad_proj/lib/python3.9/site-packages/omegaconf/dictconfig.py", line 308, in __setitem__
    self.__set_impl(key=key, value=value)
  File "/home/nshaheen/anaconda3/envs/grad_proj/lib/python3.9/site-packages/omegaconf/dictconfig.py", line 318, in __set_impl
    self._set_item_impl(key, value)
  File "/home/nshaheen/anaconda3/envs/grad_proj/lib/python3.9/site-packages/omegaconf/basecontainer.py", line 545, in _set_item_impl
    self._validate_set(key, value)
  File "/home/nshaheen/anaconda3/envs/grad_proj/lib/python3.9/site-packages/omegaconf/dictconfig.py", line 180, in _validate_set
    target = self._get_node(key) if key is not None else self
  File "/home/nshaheen/anaconda3/envs/grad_proj/lib/python3.9/site-packages/omegaconf/dictconfig.py", line 475, in _get_node
    self._validate_get(key)
  File "/home/nshaheen/anaconda3/envs/grad_proj/lib/python3.9/site-packages/omegaconf/dictconfig.py", line 164, in _validate_get
    self._format_and_raise(
  File "/home/nshaheen/anaconda3/envs/grad_proj/lib/python3.9/site-packages/omegaconf/base.py", line 231, in _format_and_raise
    format_and_raise(
  File "/home/nshaheen/anaconda3/envs/grad_proj/lib/python3.9/site-packages/omegaconf/_utils.py", line 899, in format_and_raise
    _raise(ex, cause)
  File "/home/nshaheen/anaconda3/envs/grad_proj/lib/python3.9/site-packages/omegaconf/_utils.py", line 797, in _raise
    raise ex.with_traceback(sys.exc_info()[2])  # set env var OC_CAUSE=1 for full trace
omegaconf.errors.ConfigKeyError: Key 'editable_path' is not in struct
    full_key: train.editable_path
    object_type=dict

The above exception was the direct cause of the following exception:

[36mray::ClientAppActor.run()[39m (pid=743123, ip=10.53.222.27, actor_id=3378543e5273e1b49b2db26901000000, repr=<flwr.simulation.ray_transport.ray_actor.ClientAppActor object at 0x7f927bf0b7c0>)
  File "/home/nshaheen/anaconda3/envs/grad_proj/lib/python3.9/site-packages/flwr/simulation/ray_transport/ray_actor.py", line 64, in run
    raise ClientAppException(str(ex)) from ex
flwr.client.client_app.ClientAppException: 
Exception ClientAppException occurred. Message: Key 'editable_path' is not in struct
    full_key: train.editable_path
    object_type=dict
[2024-05-06 20:51:06,577][flwr][ERROR] - Traceback (most recent call last):
  File "/home/nshaheen/anaconda3/envs/grad_proj/lib/python3.9/site-packages/flwr/simulation/app.py", line 308, in start_simulation
    hist = run_fl(
  File "/home/nshaheen/anaconda3/envs/grad_proj/lib/python3.9/site-packages/flwr/server/server.py", line 483, in run_fl
    hist, elapsed_time = server.fit(
  File "/home/nshaheen/anaconda3/envs/grad_proj/lib/python3.9/site-packages/flwr/server/server.py", line 93, in fit
    self.parameters = self._get_initial_parameters(server_round=0, timeout=timeout)
  File "/home/nshaheen/anaconda3/envs/grad_proj/lib/python3.9/site-packages/flwr/server/server.py", line 282, in _get_initial_parameters
    get_parameters_res = random_client.get_parameters(
  File "/home/nshaheen/anaconda3/envs/grad_proj/lib/python3.9/site-packages/flwr/simulation/ray_transport/ray_client_proxy.py", line 148, in get_parameters
    message_out = self._submit_job(message, timeout)
  File "/home/nshaheen/anaconda3/envs/grad_proj/lib/python3.9/site-packages/flwr/simulation/ray_transport/ray_client_proxy.py", line 87, in _submit_job
    raise ex
  File "/home/nshaheen/anaconda3/envs/grad_proj/lib/python3.9/site-packages/flwr/simulation/ray_transport/ray_client_proxy.py", line 73, in _submit_job
    out_mssg, updated_context = self.actor_pool.get_client_result(
  File "/home/nshaheen/anaconda3/envs/grad_proj/lib/python3.9/site-packages/flwr/simulation/ray_transport/ray_actor.py", line 399, in get_client_result
    return self._fetch_future_result(cid)
  File "/home/nshaheen/anaconda3/envs/grad_proj/lib/python3.9/site-packages/flwr/simulation/ray_transport/ray_actor.py", line 280, in _fetch_future_result
    res_cid, out_mssg, updated_context = ray.get(
  File "/home/nshaheen/anaconda3/envs/grad_proj/lib/python3.9/site-packages/ray/_private/auto_init_hook.py", line 24, in auto_init_wrapper
    return fn(*args, **kwargs)
  File "/home/nshaheen/anaconda3/envs/grad_proj/lib/python3.9/site-packages/ray/_private/client_mode_hook.py", line 103, in wrapper
    return func(*args, **kwargs)
  File "/home/nshaheen/anaconda3/envs/grad_proj/lib/python3.9/site-packages/ray/_private/worker.py", line 2524, in get
    raise value.as_instanceof_cause()
ray.exceptions.RayTaskError(ClientAppException): [36mray::ClientAppActor.run()[39m (pid=743123, ip=10.53.222.27, actor_id=3378543e5273e1b49b2db26901000000, repr=<flwr.simulation.ray_transport.ray_actor.ClientAppActor object at 0x7f927bf0b7c0>)
  File "/home/nshaheen/anaconda3/envs/grad_proj/lib/python3.9/site-packages/flwr/client/client_app.py", line 98, in __call__
    return self._call(message, context)
  File "/home/nshaheen/anaconda3/envs/grad_proj/lib/python3.9/site-packages/flwr/client/client_app.py", line 81, in ffn
    out_message = handle_legacy_message_from_msgtype(
  File "/home/nshaheen/anaconda3/envs/grad_proj/lib/python3.9/site-packages/flwr/client/message_handler/message_handler.py", line 96, in handle_legacy_message_from_msgtype
    client = client_fn(str(message.metadata.partition_id))
  File "/scratch/nshaheen/project/may_federated/LLaVA_flowertune/client.py", line 129, in client_fn
    return FlowerClient(
  File "/scratch/nshaheen/project/may_federated/LLaVA_flowertune/client.py", line 36, in __init__
    self.train_cfg = OmegaConf.merge(self.train_cfg, data_cfg)
  File "/home/nshaheen/anaconda3/envs/grad_proj/lib/python3.9/site-packages/omegaconf/omegaconf.py", line 273, in merge
    target.merge_with(*configs[1:])
  File "/home/nshaheen/anaconda3/envs/grad_proj/lib/python3.9/site-packages/omegaconf/basecontainer.py", line 492, in merge_with
    self._format_and_raise(key=None, value=None, cause=e)
  File "/home/nshaheen/anaconda3/envs/grad_proj/lib/python3.9/site-packages/omegaconf/base.py", line 231, in _format_and_raise
    format_and_raise(
  File "/home/nshaheen/anaconda3/envs/grad_proj/lib/python3.9/site-packages/omegaconf/_utils.py", line 819, in format_and_raise
    _raise(ex, cause)
  File "/home/nshaheen/anaconda3/envs/grad_proj/lib/python3.9/site-packages/omegaconf/_utils.py", line 797, in _raise
    raise ex.with_traceback(sys.exc_info()[2])  # set env var OC_CAUSE=1 for full trace
  File "/home/nshaheen/anaconda3/envs/grad_proj/lib/python3.9/site-packages/omegaconf/basecontainer.py", line 490, in merge_with
    self._merge_with(*others)
  File "/home/nshaheen/anaconda3/envs/grad_proj/lib/python3.9/site-packages/omegaconf/basecontainer.py", line 514, in _merge_with
    BaseContainer._map_merge(self, other)
  File "/home/nshaheen/anaconda3/envs/grad_proj/lib/python3.9/site-packages/omegaconf/basecontainer.py", line 432, in _map_merge
    dest[key] = src._get_node(key)
  File "/home/nshaheen/anaconda3/envs/grad_proj/lib/python3.9/site-packages/omegaconf/dictconfig.py", line 310, in __setitem__
    self._format_and_raise(
  File "/home/nshaheen/anaconda3/envs/grad_proj/lib/python3.9/site-packages/omegaconf/base.py", line 231, in _format_and_raise
    format_and_raise(
  File "/home/nshaheen/anaconda3/envs/grad_proj/lib/python3.9/site-packages/omegaconf/_utils.py", line 819, in format_and_raise
    _raise(ex, cause)
  File "/home/nshaheen/anaconda3/envs/grad_proj/lib/python3.9/site-packages/omegaconf/_utils.py", line 797, in _raise
    raise ex.with_traceback(sys.exc_info()[2])  # set env var OC_CAUSE=1 for full trace
  File "/home/nshaheen/anaconda3/envs/grad_proj/lib/python3.9/site-packages/omegaconf/dictconfig.py", line 308, in __setitem__
    self.__set_impl(key=key, value=value)
  File "/home/nshaheen/anaconda3/envs/grad_proj/lib/python3.9/site-packages/omegaconf/dictconfig.py", line 318, in __set_impl
    self._set_item_impl(key, value)
  File "/home/nshaheen/anaconda3/envs/grad_proj/lib/python3.9/site-packages/omegaconf/basecontainer.py", line 545, in _set_item_impl
    self._validate_set(key, value)
  File "/home/nshaheen/anaconda3/envs/grad_proj/lib/python3.9/site-packages/omegaconf/dictconfig.py", line 180, in _validate_set
    target = self._get_node(key) if key is not None else self
  File "/home/nshaheen/anaconda3/envs/grad_proj/lib/python3.9/site-packages/omegaconf/dictconfig.py", line 475, in _get_node
    self._validate_get(key)
  File "/home/nshaheen/anaconda3/envs/grad_proj/lib/python3.9/site-packages/omegaconf/dictconfig.py", line 164, in _validate_get
    self._format_and_raise(
  File "/home/nshaheen/anaconda3/envs/grad_proj/lib/python3.9/site-packages/omegaconf/base.py", line 231, in _format_and_raise
    format_and_raise(
  File "/home/nshaheen/anaconda3/envs/grad_proj/lib/python3.9/site-packages/omegaconf/_utils.py", line 899, in format_and_raise
    _raise(ex, cause)
  File "/home/nshaheen/anaconda3/envs/grad_proj/lib/python3.9/site-packages/omegaconf/_utils.py", line 797, in _raise
    raise ex.with_traceback(sys.exc_info()[2])  # set env var OC_CAUSE=1 for full trace
omegaconf.errors.ConfigKeyError: Key 'editable_path' is not in struct
    full_key: train.editable_path
    object_type=dict

The above exception was the direct cause of the following exception:

[36mray::ClientAppActor.run()[39m (pid=743123, ip=10.53.222.27, actor_id=3378543e5273e1b49b2db26901000000, repr=<flwr.simulation.ray_transport.ray_actor.ClientAppActor object at 0x7f927bf0b7c0>)
  File "/home/nshaheen/anaconda3/envs/grad_proj/lib/python3.9/site-packages/flwr/simulation/ray_transport/ray_actor.py", line 64, in run
    raise ClientAppException(str(ex)) from ex
flwr.client.client_app.ClientAppException: 
Exception ClientAppException occurred. Message: Key 'editable_path' is not in struct
    full_key: train.editable_path
    object_type=dict

[2024-05-06 20:51:06,579][flwr][ERROR] - Your simulation crashed :(. This could be because of several reasons. The most common are: 
	 > Sometimes, issues in the simulation code itself can cause crashes. It's always a good idea to double-check your code for any potential bugs or inconsistencies that might be contributing to the problem. For example: 
		 - You might be using a class attribute in your clients that hasn't been defined.
		 - There could be an incorrect method call to a 3rd party library (e.g., PyTorch).
		 - The return types of methods in your clients/strategies might be incorrect.
	 > Your system couldn't fit a single VirtualClient: try lowering `client_resources`.
	 > All the actors in your pool crashed. This could be because: 
		 - You clients hit an out-of-memory (OOM) error and actors couldn't recover from it. Try launching your simulation with more generous `client_resources` setting (i.e. it seems {'num_cpus': 2, 'num_gpus': 1.0} is not enough for your run). Use fewer concurrent actors. 
		 - You were running a multi-node simulation and all worker nodes disconnected. The head node might still be alive but cannot accommodate any actor with resources: {'num_cpus': 2, 'num_gpus': 1.0}.
Take a look at the Flower simulation examples for guidance <https://flower.ai/docs/framework/how-to-run-simulations.html>.
