[2024-05-06 22:22:44,379][flwr][INFO] - Starting Flower simulation, config: num_rounds=1, no round_timeout
[2024-05-06 22:23:13,010][flwr][INFO] - Flower VCE: Ray initialized with resources: {'node:10.53.222.27': 1.0, 'node:__internal_head__': 1.0, 'memory': 87859419751.0, 'object_store_memory': 41939751321.0, 'GPU': 1.0, 'CPU': 40.0, 'accelerator_type:V100': 1.0}
[2024-05-06 22:23:13,013][flwr][INFO] - Optimize your simulation with Flower VCE: https://flower.ai/docs/framework/how-to-run-simulations.html
[2024-05-06 22:23:13,014][flwr][INFO] - Flower VCE: Resources for each Virtual Client: {'num_cpus': 2, 'num_gpus': 1.0}
[2024-05-06 22:23:13,034][flwr][INFO] - Flower VCE: Creating VirtualClientEngineActorPool with 1 actors
[2024-05-06 22:23:13,036][flwr][INFO] - [INIT]
[2024-05-06 22:23:13,038][flwr][INFO] - Requesting initial parameters from one random client
[2024-05-06 22:25:32,397][flwr][ERROR] - Traceback (most recent call last):
  File "/home/nshaheen/anaconda3/envs/grad_proj/lib/python3.9/site-packages/flwr/simulation/ray_transport/ray_client_proxy.py", line 73, in _submit_job
    out_mssg, updated_context = self.actor_pool.get_client_result(
  File "/home/nshaheen/anaconda3/envs/grad_proj/lib/python3.9/site-packages/flwr/simulation/ray_transport/ray_actor.py", line 399, in get_client_result
    return self._fetch_future_result(cid)
  File "/home/nshaheen/anaconda3/envs/grad_proj/lib/python3.9/site-packages/flwr/simulation/ray_transport/ray_actor.py", line 280, in _fetch_future_result
    res_cid, out_mssg, updated_context = ray.get(
  File "/home/nshaheen/anaconda3/envs/grad_proj/lib/python3.9/site-packages/ray/_private/auto_init_hook.py", line 24, in auto_init_wrapper
    return fn(*args, **kwargs)
  File "/home/nshaheen/anaconda3/envs/grad_proj/lib/python3.9/site-packages/ray/_private/client_mode_hook.py", line 103, in wrapper
    return func(*args, **kwargs)
  File "/home/nshaheen/anaconda3/envs/grad_proj/lib/python3.9/site-packages/ray/_private/worker.py", line 2524, in get
    raise value.as_instanceof_cause()
ray.exceptions.RayTaskError(ClientAppException): [36mray::ClientAppActor.run()[39m (pid=761108, ip=10.53.222.27, actor_id=c466fc4b46fc1668dd6a770901000000, repr=<flwr.simulation.ray_transport.ray_actor.ClientAppActor object at 0x7fba7b74e070>)
  File "/home/nshaheen/anaconda3/envs/grad_proj/lib/python3.9/site-packages/flwr/client/client_app.py", line 98, in __call__
    return self._call(message, context)
  File "/home/nshaheen/anaconda3/envs/grad_proj/lib/python3.9/site-packages/flwr/client/client_app.py", line 81, in ffn
    out_message = handle_legacy_message_from_msgtype(
  File "/home/nshaheen/anaconda3/envs/grad_proj/lib/python3.9/site-packages/flwr/client/message_handler/message_handler.py", line 96, in handle_legacy_message_from_msgtype
    client = client_fn(str(message.metadata.partition_id))
  File "/scratch/nshaheen/project/may_federated/LLaVA_flowertune/client.py", line 132, in client_fn
    return FlowerClient(
  File "/scratch/nshaheen/project/may_federated/LLaVA_flowertune/client.py", line 44, in __init__
    self.model = get_model(model_cfg, data_cfg, tokenizer)
  File "/scratch/nshaheen/project/may_federated/LLaVA_flowertune/models.py", line 165, in get_model
    model.config.image_aspect_ratio = data_cfg.image_aspect_ratio
AttributeError: 'dict' object has no attribute 'image_aspect_ratio'

The above exception was the direct cause of the following exception:

[36mray::ClientAppActor.run()[39m (pid=761108, ip=10.53.222.27, actor_id=c466fc4b46fc1668dd6a770901000000, repr=<flwr.simulation.ray_transport.ray_actor.ClientAppActor object at 0x7fba7b74e070>)
  File "/home/nshaheen/anaconda3/envs/grad_proj/lib/python3.9/site-packages/flwr/simulation/ray_transport/ray_actor.py", line 64, in run
    raise ClientAppException(str(ex)) from ex
flwr.client.client_app.ClientAppException: 
Exception ClientAppException occurred. Message: 'dict' object has no attribute 'image_aspect_ratio'

[2024-05-06 22:25:32,399][flwr][ERROR] - [36mray::ClientAppActor.run()[39m (pid=761108, ip=10.53.222.27, actor_id=c466fc4b46fc1668dd6a770901000000, repr=<flwr.simulation.ray_transport.ray_actor.ClientAppActor object at 0x7fba7b74e070>)
  File "/home/nshaheen/anaconda3/envs/grad_proj/lib/python3.9/site-packages/flwr/client/client_app.py", line 98, in __call__
    return self._call(message, context)
  File "/home/nshaheen/anaconda3/envs/grad_proj/lib/python3.9/site-packages/flwr/client/client_app.py", line 81, in ffn
    out_message = handle_legacy_message_from_msgtype(
  File "/home/nshaheen/anaconda3/envs/grad_proj/lib/python3.9/site-packages/flwr/client/message_handler/message_handler.py", line 96, in handle_legacy_message_from_msgtype
    client = client_fn(str(message.metadata.partition_id))
  File "/scratch/nshaheen/project/may_federated/LLaVA_flowertune/client.py", line 132, in client_fn
    return FlowerClient(
  File "/scratch/nshaheen/project/may_federated/LLaVA_flowertune/client.py", line 44, in __init__
    self.model = get_model(model_cfg, data_cfg, tokenizer)
  File "/scratch/nshaheen/project/may_federated/LLaVA_flowertune/models.py", line 165, in get_model
    model.config.image_aspect_ratio = data_cfg.image_aspect_ratio
AttributeError: 'dict' object has no attribute 'image_aspect_ratio'

The above exception was the direct cause of the following exception:

[36mray::ClientAppActor.run()[39m (pid=761108, ip=10.53.222.27, actor_id=c466fc4b46fc1668dd6a770901000000, repr=<flwr.simulation.ray_transport.ray_actor.ClientAppActor object at 0x7fba7b74e070>)
  File "/home/nshaheen/anaconda3/envs/grad_proj/lib/python3.9/site-packages/flwr/simulation/ray_transport/ray_actor.py", line 64, in run
    raise ClientAppException(str(ex)) from ex
flwr.client.client_app.ClientAppException: 
Exception ClientAppException occurred. Message: 'dict' object has no attribute 'image_aspect_ratio'
[2024-05-06 22:25:32,401][flwr][ERROR] - [36mray::ClientAppActor.run()[39m (pid=761108, ip=10.53.222.27, actor_id=c466fc4b46fc1668dd6a770901000000, repr=<flwr.simulation.ray_transport.ray_actor.ClientAppActor object at 0x7fba7b74e070>)
  File "/home/nshaheen/anaconda3/envs/grad_proj/lib/python3.9/site-packages/flwr/client/client_app.py", line 98, in __call__
    return self._call(message, context)
  File "/home/nshaheen/anaconda3/envs/grad_proj/lib/python3.9/site-packages/flwr/client/client_app.py", line 81, in ffn
    out_message = handle_legacy_message_from_msgtype(
  File "/home/nshaheen/anaconda3/envs/grad_proj/lib/python3.9/site-packages/flwr/client/message_handler/message_handler.py", line 96, in handle_legacy_message_from_msgtype
    client = client_fn(str(message.metadata.partition_id))
  File "/scratch/nshaheen/project/may_federated/LLaVA_flowertune/client.py", line 132, in client_fn
    return FlowerClient(
  File "/scratch/nshaheen/project/may_federated/LLaVA_flowertune/client.py", line 44, in __init__
    self.model = get_model(model_cfg, data_cfg, tokenizer)
  File "/scratch/nshaheen/project/may_federated/LLaVA_flowertune/models.py", line 165, in get_model
    model.config.image_aspect_ratio = data_cfg.image_aspect_ratio
AttributeError: 'dict' object has no attribute 'image_aspect_ratio'

The above exception was the direct cause of the following exception:

[36mray::ClientAppActor.run()[39m (pid=761108, ip=10.53.222.27, actor_id=c466fc4b46fc1668dd6a770901000000, repr=<flwr.simulation.ray_transport.ray_actor.ClientAppActor object at 0x7fba7b74e070>)
  File "/home/nshaheen/anaconda3/envs/grad_proj/lib/python3.9/site-packages/flwr/simulation/ray_transport/ray_actor.py", line 64, in run
    raise ClientAppException(str(ex)) from ex
flwr.client.client_app.ClientAppException: 
Exception ClientAppException occurred. Message: 'dict' object has no attribute 'image_aspect_ratio'
[2024-05-06 22:25:32,408][flwr][ERROR] - Traceback (most recent call last):
  File "/home/nshaheen/anaconda3/envs/grad_proj/lib/python3.9/site-packages/flwr/simulation/app.py", line 308, in start_simulation
    hist = run_fl(
  File "/home/nshaheen/anaconda3/envs/grad_proj/lib/python3.9/site-packages/flwr/server/server.py", line 483, in run_fl
    hist, elapsed_time = server.fit(
  File "/home/nshaheen/anaconda3/envs/grad_proj/lib/python3.9/site-packages/flwr/server/server.py", line 93, in fit
    self.parameters = self._get_initial_parameters(server_round=0, timeout=timeout)
  File "/home/nshaheen/anaconda3/envs/grad_proj/lib/python3.9/site-packages/flwr/server/server.py", line 282, in _get_initial_parameters
    get_parameters_res = random_client.get_parameters(
  File "/home/nshaheen/anaconda3/envs/grad_proj/lib/python3.9/site-packages/flwr/simulation/ray_transport/ray_client_proxy.py", line 148, in get_parameters
    message_out = self._submit_job(message, timeout)
  File "/home/nshaheen/anaconda3/envs/grad_proj/lib/python3.9/site-packages/flwr/simulation/ray_transport/ray_client_proxy.py", line 87, in _submit_job
    raise ex
  File "/home/nshaheen/anaconda3/envs/grad_proj/lib/python3.9/site-packages/flwr/simulation/ray_transport/ray_client_proxy.py", line 73, in _submit_job
    out_mssg, updated_context = self.actor_pool.get_client_result(
  File "/home/nshaheen/anaconda3/envs/grad_proj/lib/python3.9/site-packages/flwr/simulation/ray_transport/ray_actor.py", line 399, in get_client_result
    return self._fetch_future_result(cid)
  File "/home/nshaheen/anaconda3/envs/grad_proj/lib/python3.9/site-packages/flwr/simulation/ray_transport/ray_actor.py", line 280, in _fetch_future_result
    res_cid, out_mssg, updated_context = ray.get(
  File "/home/nshaheen/anaconda3/envs/grad_proj/lib/python3.9/site-packages/ray/_private/auto_init_hook.py", line 24, in auto_init_wrapper
    return fn(*args, **kwargs)
  File "/home/nshaheen/anaconda3/envs/grad_proj/lib/python3.9/site-packages/ray/_private/client_mode_hook.py", line 103, in wrapper
    return func(*args, **kwargs)
  File "/home/nshaheen/anaconda3/envs/grad_proj/lib/python3.9/site-packages/ray/_private/worker.py", line 2524, in get
    raise value.as_instanceof_cause()
ray.exceptions.RayTaskError(ClientAppException): [36mray::ClientAppActor.run()[39m (pid=761108, ip=10.53.222.27, actor_id=c466fc4b46fc1668dd6a770901000000, repr=<flwr.simulation.ray_transport.ray_actor.ClientAppActor object at 0x7fba7b74e070>)
  File "/home/nshaheen/anaconda3/envs/grad_proj/lib/python3.9/site-packages/flwr/client/client_app.py", line 98, in __call__
    return self._call(message, context)
  File "/home/nshaheen/anaconda3/envs/grad_proj/lib/python3.9/site-packages/flwr/client/client_app.py", line 81, in ffn
    out_message = handle_legacy_message_from_msgtype(
  File "/home/nshaheen/anaconda3/envs/grad_proj/lib/python3.9/site-packages/flwr/client/message_handler/message_handler.py", line 96, in handle_legacy_message_from_msgtype
    client = client_fn(str(message.metadata.partition_id))
  File "/scratch/nshaheen/project/may_federated/LLaVA_flowertune/client.py", line 132, in client_fn
    return FlowerClient(
  File "/scratch/nshaheen/project/may_federated/LLaVA_flowertune/client.py", line 44, in __init__
    self.model = get_model(model_cfg, data_cfg, tokenizer)
  File "/scratch/nshaheen/project/may_federated/LLaVA_flowertune/models.py", line 165, in get_model
    model.config.image_aspect_ratio = data_cfg.image_aspect_ratio
AttributeError: 'dict' object has no attribute 'image_aspect_ratio'

The above exception was the direct cause of the following exception:

[36mray::ClientAppActor.run()[39m (pid=761108, ip=10.53.222.27, actor_id=c466fc4b46fc1668dd6a770901000000, repr=<flwr.simulation.ray_transport.ray_actor.ClientAppActor object at 0x7fba7b74e070>)
  File "/home/nshaheen/anaconda3/envs/grad_proj/lib/python3.9/site-packages/flwr/simulation/ray_transport/ray_actor.py", line 64, in run
    raise ClientAppException(str(ex)) from ex
flwr.client.client_app.ClientAppException: 
Exception ClientAppException occurred. Message: 'dict' object has no attribute 'image_aspect_ratio'

[2024-05-06 22:25:32,410][flwr][ERROR] - Your simulation crashed :(. This could be because of several reasons. The most common are: 
	 > Sometimes, issues in the simulation code itself can cause crashes. It's always a good idea to double-check your code for any potential bugs or inconsistencies that might be contributing to the problem. For example: 
		 - You might be using a class attribute in your clients that hasn't been defined.
		 - There could be an incorrect method call to a 3rd party library (e.g., PyTorch).
		 - The return types of methods in your clients/strategies might be incorrect.
	 > Your system couldn't fit a single VirtualClient: try lowering `client_resources`.
	 > All the actors in your pool crashed. This could be because: 
		 - You clients hit an out-of-memory (OOM) error and actors couldn't recover from it. Try launching your simulation with more generous `client_resources` setting (i.e. it seems {'num_cpus': 2, 'num_gpus': 1.0} is not enough for your run). Use fewer concurrent actors. 
		 - You were running a multi-node simulation and all worker nodes disconnected. The head node might still be alive but cannot accommodate any actor with resources: {'num_cpus': 2, 'num_gpus': 1.0}.
Take a look at the Flower simulation examples for guidance <https://flower.ai/docs/framework/how-to-run-simulations.html>.
